Workbook

Sheet Resumen
A1: MÓDULOS | B1: OBJETIVOS | C1: NUM ACT | D1: ACTIVIDAD | E1: FEEDBACK | F1: CONCLUSIÓN | G1: CONTENIDOS
A2: ='Cont-Obj'!A:A -> Módulo 1. La seguridad alimentaria empieza contigo | B2: ='Cont-Obj'!B:B -> O1.1 Conocer la definición de manipulador de alimentos | C2: ='Cont-Obj'!C:C -> 1 | D2: {=IF(C2:C1001="","",IFERROR(VLOOKUP(C2:C1001,'Actividades de aprendizaje'!A:E,{2,3,4},FALSE),""))} -> Mesa del comedor | E2: Actividad de lectura: ¿Qué es un manipulador de alimentos? Enunciado: Antes de empezar a moverte por el restaurante, hay algo que debes tener claro: qué significa ser manipulador de alimentos. Tranquilo, es más sencillo de lo que parece: Un manipulador de alimentos es cualquier persona que, por su trabajo, entra en contacto con alimentos o realiza tareas que pueden influir en su seguridad. Fíjate en la última parte: 'cualquier persona que... realiza tareas que pueden influir en su seguridad'. Eso incluye a mucha más gente de la que parece. De hecho, ahora mismo voy a ponerte a prueba con algunos ejemplos. ¿Preparado?" | G2: ='Cont-Obj'!E:E -> 1.1 ¿Qué es un manipulador de alimentos?
A3: ='Cont-Obj'!A:A -> Módulo 1. La seguridad alimentaria empieza contigo | B3: ='Cont-Obj'!B:B -> O1.2 Identificar qué puestos de trabajo implican manipulación de alimentos dentro de la cadena alimentaria. | C3: ='Cont-Obj'!C:C -> 2 | D3: Mesa del comedor (vista desde arriba) | E3: Título de la actividad: ¿Quién es manipulador de alimentos? Enunciado: No todos los manipuladores de alimentos son cocineros. En esta actividad vas a conocer a distintas personas y sus puestos de trabajo. Lee con atención su carnet: su nombre, su oficio y lo que hace en su día a día. Tu misión es decidir si su trabajo implica manipular alimentos: 👉 Desliza la tarjeta a la derecha si crees que SÍ es manipulador de alimentos. 👈 Desliza la tarjeta a la izquierda si crees que NO lo es. ¡Adelante, detective!" Descripción: En el centro de la pantalla aparecerá una tarjeta con formato de carnet de identidad. Incluirá una ilustración de la persona de cabeza a pecho, vestida con su uniforme, y a la izquierda su nombre, puesto de trabajo y una breve descripción de sus funciones. El alumno deberá hacer swipe a la derecha si considera que es manipulador de alimentos y a la izquierda si considera que no. Personajes / tarjetas (Nombre, puesto y descripción): - Óscar Fernández: Cocinero del restaurante El Caserío. Me encargo de preparar los platos de la carta para que los clientes queden satisfechos. - Laura Martín: Camarera de la cafetería La plaza. Sirvo los platos y las bebidas. Además atiendo a los clientes en la sala. - Pablo Sánchez: Personal de cafetería. Preparo cafés, bebidas y otros productos que se sirven a los clientes. - Marta López: Transportista de la frutería Hermanos López. Reparto la mercancía a los restaurantes de la zona. - Miguel Rodríguez: Repartidor de la pizzería Primavera. Llevo en moto los pedidos a domicilio. - Javier Ruiz: Mozo de almacen de Supermercados Luna. Recibo las mercancías, compruebo los productos y los coloco en las zonas de almacenamiento correspondientes. - Ana García: Dependienta de la carnicería Loli. Atiendo a los clientes, preparo y entrego los productos cárnicos que solicitan. - Sonia Moreno: Operaria de envasado. Empaqueto y etiqueto comida preparada en envases herméticos. - Carmen Díaz: Personal de limpieza. Me encargo de mantener limpias las oficinas y las zonas comunes del edificio. - Sergio Navarro: Comercial de Homesec. Visito establecimientos para presentar nuestros productos y explicar sus características a los clientes. - Elena Torres: Recepcionista de hotel Gold. Recibo a los clientes, gestiono sus entradas y salidas y atiendo sus consultas. Respuesta correcta: Los ocho primeros son manipuladores de alimentos. Los tres últimos no lo son. | F3: El feedback será específico para cada personaje, pero mantendrá la misma estructura tanto para respuestas correctas como incorrectas: Si es manipulador: - ¡Correcto!/¡Incorrecto! Óscar es manipulador de alimentos porque, como cocinero, está en contacto directo con los alimentos durante su preparación. - ¡Correcto!/¡Incorrecto! Laura es manipuladora de alimentos porque, como camarera tiene contacto con los alimentos durante el servicio de los mismos. - ¡Correcto!/¡Incorrecto! Pablo es manipulador de alimentos porque, como personal de cafetería, prepara y sirve cafés, bebidas y otros productos que van destinados directamente al consumo de los clientes. - ¡Correcto!/¡Incorrecto! Marta es manipuladora de alimentos porque, como transportista de una frutería, traslada mercancías alimentarias y debe garantizar que se mantengan en condiciones adecuadas hasta su entrega a los restaurantes. - ¡Correcto!/¡Incorrecto! Miguel es manipulador de alimentos porque, como repartidor de una pizzería, transporta los pedidos de comida hasta el domicilio de los clientes, velando por que lleguen en buen estado. - ¡Correcto!/¡Incorrecto! Javier es manipulador de alimentos porque, como mozo de almacén de un supermercado, recibe, comprueba y coloca productos alimentarios en las zonas de almacenamiento correspondientes. - ¡Correcto!/¡Incorrecto! Ana es manipuladora de alimentos porque, como dependienta de una carnicería, prepara y entrega directamente a los clientes los productos cárnicos que solicitan. - ¡Correcto!/¡Incorrecto! Sonia es manipuladora de alimentos porque, como operaria de envasado, empaqueta y etiqueta comida preparada en envases herméticos, estando en contacto directo con los alimentos. Si no es manipulador: - ¡Correcto!/¡Incorrecto! Carmen no es manipuladora de alimentos porque realiza tareas de limpieza en oficinas y zonas comunes que no están relacionadas con la manipulación de alimentos ni con superficies destinadas a ellos. - ¡Correcto!/¡Incorrecto! Sergio no es manipulador de alimentos porque sus funciones se limitan a presentar productos de un sector que no interviene en ninguna tarea relacionada con los alimentos. - ¡Correcto!/¡Incorrecto! Elena no es manipuladora de alimentos porque sus funciones se limitan a la recepción y atención de clientes y no interviene en ninguna tarea relacionada con los alimentos. | G3: ='Cont-Obj'!E:E -> 1.1 ¿Qué es un manipulador de alimentos?
A4: ='Cont-Obj'!A:A -> Módulo 1. La seguridad alimentaria empieza contigo | B4: ='Cont-Obj'!B:B -> O1.3 Comprender la importancia del papel del manipulador de alimentos en la seguridad y salud de los consumidores. | C4: ='Cont-Obj'!C:C -> 3 | D4: Recepción (tablet) | E4: Título de la actividad: Cámaras de seguridad: del manipulador al consumidor. Enunciado: Bienvenido/a al sistema de videovigilancia del restaurante. Observa las grabaciones de la cámara de seguridad. Tu misión es decidir si lo que ves supone un riesgo para la seguridad alimentaria y averiguar por qué es importante la actuación del manipulador de alimentos. En algunos casos, tendrás que ir más allá y detectar qué consecuencias podría tener cada situación para el consumidor. Analiza cada escena como si fueras el responsable de seguridad alimentaria del local. ¡Adelante! Descripción: Actividad interactiva de análisis causa-efecto. El alumnado visualiza una galería de vídeos que simulan las cámaras de seguridad de un establecimiento de hostelería. Para cada grabación debe: (1) decidir si la situación supone un riesgo para la seguridad alimentaria; (2) si hay riesgo, identificar por qué es importante la actuación del manipulador; y (3) en varios casos, determinar qué consecuencia podría tener esa situación para el consumidor. Se trabaja la relación actuación del manipulador → efecto sobre el alimento → posible consecuencia para el consumidor, más allá de la simple identificación de buenas y malas prácticas. Situaciones que se visualizan en los vídeos: Vídeo 1: En la cocina, un cocinero coge tomates para cortarlos y ensalzarlos, pero no se ha lavado las manos previamente. Pregunta 1. ¿Supone un riesgo para la seguridad alimentaria? ✅ Sí No Pregunta 2. ¿Por qué es importante que el manipulador se lave las manos antes de manipular los alimentos? ✅ A. Porque puede transferir microorganismos al alimento. ❌ B. Porque los alimentos tendrán mejor aspecto. ❌ C. Porque terminará antes la preparación. ❌D. Porque evitará que el alimento se enfríe. Vídeo 2: Una cocinera corta pollo crudo y utiliza una tabla y un cuchillo limpios, específicos para ese uso. Pregunta 1. ¿Supone un riesgo para la seguridad alimentaria? Sí ✅ No (Al ser una práctica correcta, no avanza a más preguntas. Se pasa al siguiente vídeo con feedback positivo.) Vídeo 3: Un ayudante de cocina utiliza un cuchillo y una tabla que tienen restos de comida seca de usos anteriores para trocear verduras. Pregunta 1. ¿Supone un riesgo para la seguridad alimentaria? ✅ Sí No Pregunta 2. ¿Por qué es importante utilizar utensilios limpios durante la preparación de los alimentos? ✅ A. Porque los restos y microorganismos de usos anteriores pueden pasar al alimento. ❌ B. Porque es suficiente retirar los restos de comida antes de utilizar de nuevo los utensilios. ❌ C. Porque los utensilios deben limpiarse al terminar el servicio, aunque se utilicen con distintos alimentos durante la preparación. ❌ D. Porque basta con utilizar utensilios diferentes para cada alimento, aunque no se hayan limpiado previamente. Vídeo 4: Un trabajador saca un recipiente con mayonesa casera de la nevera y lo deja encima de la encimera durante horas mientras prepara otras tareas, a temperatura ambiente. Pregunta 1. ¿Supone un riesgo para la seguridad alimentaria? ✅ Sí No Pregunta 2. ¿Por qué es importante mantener los alimentos perecederos a temperatura segura? ✅ A. Porque a temperatura ambiente los microorganismos pueden multiplicarse rápidamente en el alimento. ❌ B. Porque es suficiente mantener el alimento refrigerado hasta el momento de empezar a prepararlo. ❌ C. Porque mantener el alimento tapado permite dejarlo fuera de la nevera mientras se realizan otras tareas. ❌ D. Porque la temperatura solo necesita controlarse cuando el alimento va a conservarse hasta el día siguiente.Pregunta 3. ¿Qué consecuencia podría tener esta situación para el consumidor? Pregunta 3. ¿Qué consecuencia podría tener esta situación para el consumidor? ✅ A. Que el alimento pueda contener microorganismos capaces de causar una enfermedad alimentaria. ❌ B. Que el alimento se deteriore antes, pero sin que ello suponga necesariamente un riesgo para el consumidor. ❌ C. Que el alimento conserve sus condiciones de seguridad siempre que se refrigere antes de servirlo. ❌ D. Que el alimento solo represente un riesgo si presenta cambios visibles en su aspecto u olor. Vídeo 5: En la cámara frigorífica, se ve cómo un cocinero comprueba con un termómetro que los lácteos y las carnes están a la temperatura establecida y anota el registro. Pregunta 1. ¿Supone un riesgo para la seguridad alimentaria? Sí ✅ No (Práctica correcta: no avanza a más preguntas.) Vídeo 6: Un manipulador coloca pechugas de pollo crudas en la misma bandeja donde hay lechuga ya lavada y lista para servir. Pregunta 1. ¿Supone un riesgo para la seguridad alimentaria? ✅ Sí No Pregunta 2. ¿Por qué es importante separar los alimentos crudos de los listos para consumir? ✅ A. Porque los microorganismos del pollo crudo pueden pasar a la lechuga. ❌ B. Porque los alimentos crudos deben mantenerse separados únicamente durante su almacenamiento en la cámara frigorífica. ❌ C. Porque utilizar una bandeja para cada alimento es suficiente, aunque después se coloquen una junto a otra y entren en contacto. ❌ D. Porque los alimentos listos para consumir solo necesitan separarse de los crudos cuando van a servirse sin lavar. Pregunta 3. ¿Qué consecuencia podría tener esta situación para el consumidor? ✅ A. Que la lechuga se contamine y transmita microorganismos al consumidor al ingerirla. ❌ B. Que el pollo necesite cocinarse durante más tiempo para compensar el contacto con la lechuga. ❌ C. Que la lechuga pierda frescura durante su conservación, aunque no se vea afectada su seguridad alimentaria. ❌ D. Que sea suficiente retirar las hojas que han estado en contacto directo con el pollo para eliminar el riesgo. Vídeo 7: En la zona de preparación, un cocinero tiene en una bandeja la carne cruda y, en otra separada, los vegetales listos para consumir. Pregunta 1. ¿Supone un riesgo para la seguridad alimentaria? Sí ✅ No (Práctica correcta: no avanza a más preguntas.) Vídeo 8: Un trabajador consulta la ficha de procedimiento del local, se coloca el gorro y los guantes limpios y sigue los pasos indicados para manipular un alimento. Pregunta 1. ¿Supone un riesgo para la seguridad alimentaria? Sí ✅ No (Práctica correcta: no avanza a más preguntas.) | F4: Feedback de la Pregunta 1 (¿Supone un riesgo?): Acierto: ¡Correcto! Has identificado bien si la situación supone o no un riesgo para la seguridad alimentaria. Error: Revisa la escena con calma. ¿La actuación del manipulador puede contaminar el alimento? ¿O se trata de una práctica segura? Recuerda: los riesgos no siempre se ven a simple vista. Feedback de la Pregunta 2 (¿Por qué es importante?): Acierto: ¡Exacto! Has entendido por qué la actuación del manipulador afecta directamente a la seguridad del alimento. Error: Vuelve a pensarlo: la actuación del manipulador no es una formalidad, tiene un efecto real sobre el alimento. ¿Qué puede pasarle al alimento si esa actuación es incorrecta? Feedback de la Pregunta 3 (¿Qué consecuencia para el consumidor?): Acierto: ¡Perfecto! Has llegado hasta el final de la cadena: la actuación del manipulador puede acabar afectando a la salud del consumidor. Error: Recuerda la cadena completa: actuación incorrecta del manipulador → contaminación del alimento → riesgo para el consumidor. ¿Cuál de las opciones refleja ese efecto real sobre la salud? | G4: ='Cont-Obj'!E:E -> 1.2 ¿Por qué es tan importante tu trabajo?
A5: ='Cont-Obj'!A:A -> Módulo 1. La seguridad alimentaria empieza contigo | B5: ='Cont-Obj'!B:B -> O1.4 Reconocer las principales consecuencias que puede tener una manipulación incorrecta de los alimentos para los consumidores, el establecimiento y el propio manipulador. | C5: ='Cont-Obj'!C:C -> 4 | D5: Recepción (Actividad oral: David te narra situaciones, debes contestar pulsando botones: Consumidor, Establecimiento y Manipulador) | E5: Título de la actividad: ¿A quién afecta? Enunciado: Cuando un alimento no se manipula correctamente, las consecuencias no afectan solo a una parte. Detrás de cada error hay personas, negocios y profesionales que pueden salir perjudicados. En pantalla irán apareciendo diferentes consecuencias. Tu tarea es arrastrar cada una al cajón correcto según a quién afecta principalmente: 🧑 Consumidor → si la consecuencia recae sobre la salud o la experiencia de quien consume el alimento. 🏪 Establecimiento → si la consecuencia afecta al negocio, su funcionamiento o su economía. 👨‍🍳 Manipulador → si la consecuencia recae sobre el propio trabajador que manipula los alimentos. Lee bien cada tarjeta antes de arrastrarla: algunas pueden parecer similares, pero el impacto principal marca la diferencia. ¡Coloca cada consecuencia en su cajón! Descripción: Actividad interactiva de clasificación por arrastre (drag and drop). En el centro de la pantalla van apareciendo, una a una, distintas consecuencias derivadas de una manipulación incorrecta de los alimentos. El alumnado debe arrastrar cada consecuencia al cajón correspondiente según quién se ve afectado: Consumidor, Establecimiento o Manipulador. Se trabajan los tres ámbitos de impacto de la seguridad alimentaria: salud, negocio y responsabilidad profesional. Consecuencias a clasificar: - Un cliente enferma después de consumir un alimento contaminado. → Consumidor - Un cliente tiene que recibir atención médica después de consumir un alimento contaminado. → Consumidor - Una persona alérgica sufre una reacción grave por una gestión incorrecta de un alérgeno. → Consumidor - El establecimiento recibe quejas y reclamaciones de los clientes. → Establecimiento - Se producen devoluciones o es necesario retirar productos. → Establecimiento - Se desperdician alimentos como consecuencia de un problema de seguridad alimentaria. → Establecimiento - Un cliente pierde la confianza en el establecimiento después de sufrir un problema relacionado con un alimento. → Establecimiento - El negocio recibe una inspección o una sanción. → Establecimiento - El trabajador puede recibir una sanción laboral por incumplir los procedimientos de seguridad alimentaria. → Manipulador - El trabajador puede enfermar al entrar en contacto con alimentos contaminados durante una manipulación incorrecta. → Manipulador | F5: Respuestas correctas: - Consumidor: ¡Correcto! Cuando la consecuencia recae sobre la salud o la seguridad de quien consume el alimento, estamos ante un impacto directo en el consumidor. Enfermedades, intoxicaciones o reacciones alérgicas graves son las consecuencias más serias de una mala manipulación. - Establecimiento: ¡Muy bien! Quejas, devoluciones, retirada de productos, desperdicio de alimentos, pérdidas económicas, inspecciones o sanciones afectan directamente al negocio y a su reputación. - Manipulador: ¡Exacto! El trabajador que ignora los procedimientos puede enfrentarse a consecuencias laborales y, en casos graves, a responsabilidades administrativas, civiles o incluso penales. Respuestas incorrectas: - Si has arrastrado la tarjeta al cajón "Consumidor" y no correspondía: Cuidado: no todas las consecuencias graves afectan al consumidor. Si la tarjeta hablaba de sanciones, pérdidas, quejas o responsabilidades del trabajador, el afectado no es quien consume el alimento. Pregúntate de nuevo: ¿quién sufre directamente esta consecuencia? - Si has arrastrado la tarjeta al cajón "Establecimiento" y no correspondía: Cuidado: no todo lo que ocurre en el local afecta al negocio como tal. Si la tarjeta hablaba de enfermedades, reacciones alérgicas o responsabilidades del trabajador, el afectado no es el establecimiento. Pregúntate de nuevo: ¿quién sufre directamente esta consecuencia? - Si has arrastrado la tarjeta al cajón "Manipulador" y no correspondía: Cuidado: no todas las consecuencias recaen sobre el trabajador. Si la tarjeta hablaba de enfermedades del cliente, quejas, pérdidas económicas o sanciones al negocio, el afectado no es el manipulador. Pregúntate de nuevo: ¿quién sufre directamente esta consecuencia? | G5: ='Cont-Obj'!E:E -> 1.3 ¿Qué puede ocurrir si no manipulamos bien los alimentos?
A6: ='Cont-Obj'!A:A -> Módulo 1. La seguridad alimentaria empieza contigo | B6: ='Cont-Obj'!B:B -> O1.5 Identificar las reglas básicas de seguridad alimentaria durante las tareas de manipulación. | C6: ='Cont-Obj'!C:C -> 5 | D6: Recepción (tablet) | E6: Título de la actividad: Detectives de la cocina: encuentra las 8 reglas básicas. Enunciado: Esta cocina tiene un problema: en algún punto de la imagen se está incumpliendo cada una de las 8 reglas básicas para trabajar con seguridad alimentaria. A la izquierda tienes las 8 reglas. Pasa el ratón por la imagen para descubrir los puntos calientes y arrastra cada regla hasta el punto donde creas que se está incumpliendo. Fíjate bien en todos los detalles de la imagen. ¡Demuestra que sabes leer una cocina como un profesional!" Descripción: Actividad de emparejamiento por arrastre. A la izquierda de la pantalla aparecen las 8 reglas básicas para trabajar con seguridad alimentaria y a la derecha se muestra una imagen de una cocina profesional con 8 puntos calientes ocultos. El alumnado debe arrastrar cada regla al punto de la imagen donde se está incumpliendo o poniendo en riesgo esa regla concreta. Reglas y punto caliente correcto: Regla --> Punto caliente 1. Mantener una buena higiene personal --> Manos del cocinero sucias. 2. Evitar la contaminación de los alimentos --> Bote de limpieza abierto junto a una caja de zanahorias. 3. Separar los alimentos crudos de los cocinados o listos para consumir --> Bandeja de carne cruda junto a ensalada lista para consumir en la encimera de trabajo. 4. Mantener los alimentos a temperaturas seguras --> Termómetro de nevera marcando 12 °C. 5. Limpiar y desinfectar correctamente los utensilios, equipos e instalaciones --> Cuchillos sucios colocados en su sitio en la pared. 6. Utilizar de forma segura los productos de limpieza --> Producto de limpieza mal cerrado y goteando bajo el fregadero. 7. Gestionar correctamente los alérgenos --> Comanda que especifica "sin huevo" la ensalada preparada en la mesa de trabajo que se visualiza con huevo. 8. Seguir los procedimientos establecidos por el establecimiento. --> Plato cerámica azul con patatas fritas en el pase para salir (en la pared un cartel con los tipos de emplatado, las patatas fritas van en una bandeja metálica) | F6: Feedback por acierto: Regla 1 – ¡Correcto! Las manos sucias del cocinero son el punto donde se incumple esta regla. Una higiene personal deficiente es una de las principales vías de contaminación de los alimentos. Regla 2 – ¡Bien visto! El bote de limpieza abierto junto a los alimentos puede contaminarlos con sustancias químicas. Los productos químicos nunca deben estar cerca de los alimentos. Regla 3 – ¡Exacto! La carne cruda junto a la ensalada lista para consumir es un caso claro de contaminación cruzada. Regla 4 – ¡Muy bien! Un termómetro de nevera marcando 12 °C indica que los alimentos no están a la temperatura segura establecida. La cadena de frío está rota. Regla 5 – ¡Correcto! Unos cuchillos sucios guardados en su sitio no solo incumplen esta regla: pueden contaminar el próximo alimento que se corte con ellos. Regla 6 – ¡Bien detectado! Un producto químico mal cerrado y goteando bajo el fregadero indican un uso y almacenamiento inadecuados de los productos de limpieza. Regla 7 – ¡Exacto! Una comanda que especifica "sin huevo" la ensalada exige una gestión rigurosa del alérgeno: hay que evitar cualquier contacto con el huevo para proteger al cliente. Regla 8 – ¡Correcto! El cartel de emplatado refleja un procedimiento que el manipulador debe conocer y seguir en su trabajo diario. Feedback por error: - Si suelta la regla en un punto ocupado por otra regla: "Ese punto caliente ya está relacionado con otra regla. Fíjate de nuevo en los detalles de la imagen y busca el lugar exacto donde se incumple esta regla." - Si suelta la regla en un punto que no le corresponde: "Casi. Este punto caliente no se corresponde con esta regla. Vuelve a leer la regla y observa con atención qué está ocurriendo en la cocina." | G6: ='Cont-Obj'!E:E -> 1.4 Las reglas básicas para trabajar con seguridad
A7: ='Cont-Obj'!A:A -> Módulo 1. La seguridad alimentaria empieza contigo | B7: ='Cont-Obj'!B:B -> O7.1 Comprender la importancia del trabajo coordinado de todas las personas del establecimiento para garantizar la seguridad alimentaria. | C7: ='Cont-Obj'!C:C | G7: ='Cont-Obj'!E:E -> 1.5 Tu responsabilidad como manipulador de alimentos
A8: ='Cont-Obj'!A:A -> Módulo 2. Higiene personal del manipulador | B8: ='Cont-Obj'!B:B -> O2.1 Conocer las condiciones de salud que pueden afectar a la seguridad de los alimentos. | C8: ='Cont-Obj'!C:C -> 6 | D8: Vestudario (Privado) | E8: Actividad de lectura: Enunciado: | G8: ='Cont-Obj'!E:E -> 2.1 La higiene empieza por ti
A9: ='Cont-Obj'!A:A -> Módulo 2. Higiene personal del manipulador | B9: ='Cont-Obj'!B:B -> O2.1 Conocer las condiciones de salud que pueden afectar a la seguridad de los alimentos. | C9: ='Cont-Obj'!C:C -> 7 | D9: Vestuario (Vista Pared) | E9: Actividad de lectura: Enunciado: | G9: ='Cont-Obj'!E:E -> 2.1 La higiene empieza por ti
A10: ='Cont-Obj'!A:A -> Módulo 2. Higiene personal del manipulador | B10: ='Cont-Obj'!B:B -> O2.2 Aplicar correctamente las normas de higiene personal y utilización del uniforme durante la manipulación de alimentos. | C10: ='Cont-Obj'!C:C -> 8 | D10: Vestuario | E10: Título de la actividad: Antes de comenzar, revisa tu uniforme e higiene. Enunciado: Cuatro compañeros están a punto de empezar su jornada en la cocina. Antes de entrar, hay que revisar que su aspecto sea el adecuado: uniforme completo y limpio, higiene personal correcta y sin objetos que puedan contaminar los alimentos o suponer un riesgo. Observa bien a cada personaje y pulsa sobre todos los elementos que deban modificarse, retirarse o corregirse. ¡No se te puede escapar ni uno! Cuando los tengas todos, ese trabajador estará listo para empezar. Descripción: Actividad interactiva de observación y selección. En el centro de la pantalla aparecen cuatro trabajadores en el vestuario, de frente y vestidos con su uniforme (o con elementos que deben corregir). El alumnado debe pulsar sobre cada elemento de la indumentaria o de la higiene personal que deba modificarse, retirarse o corregirse para poder comenzar la jornada de forma higiénica y segura. Se trabaja la importancia del uniforme limpio, la higiene personal y la correcta utilización de los equipos de protección. Personaje 1 – Hombre con camisa blanca, pantalón negro largo, gorro y zapatos negros apropiados. Elementos a corregir: Barba larga → pulsar para poner redecilla de protección. Uñas sucias → pulsar para limpiar la suciedad bajo las uñas. Móvil en el bolsillo → pulsar el bolsillo para retirarlo. Pendiente largo en la oreja → pulsar la oreja para quitarlo. Personaje 2 – Hombre con camiseta de tirantes blanca, pantalón negro y zapatos apropiados. Elementos a corregir: Camiseta de tirantes → pulsar para cambiarla por la camisa del uniforme. Reloj en la muñeca → pulsar la muñeca para quitarlo. Mancha en el pantalón → pulsar la mancha para eliminarla. Sin gorro → pulsar la cabeza para ponerse el gorro de cocina. Personaje 3 – Mujer con camisa blanca, pantalón negro largo y zapatos apropiados. Elementos a corregir: Pendientes enormes → pulsar las orejas para quitarlos. Brazalete → pulsar la muñeca para quitarlo. Uñas largas → pulsar las manos para cortarlas. Sin gorro → pulsar la cabeza para ponerse el gorro de cocina. Personaje 4 – Mujer con camisa blanca, pantalón negro, gorro de cocina y zapatos de tacón. Elementos a corregir: Pelo suelto → pulsar el pelo para recogerlo. Mal olor en las axilas → pulsar las axilas para corregir la higiene personal. Zapatos de tacón → pulsar los zapatos para sustituirlos por calzado apropiado. Uñas pintadas de rojo → pulsar las manos para retirar el esmalte. | F10: Feedback por acierto: Personaje 1: - Barba larga: ¡Bien! La barba puede acumular microorganismos y restos de comida. Debe cubrirse con una redecilla de protección. - Uñas sucias: ¡Correcto! Las uñas sucias son un foco de contaminación. Hay que mantenerlas cortas y limpias. - Móvil en el bolsillo: ¡Muy bien! El móvil acumula microorganismos y no debe llevarse durante la manipulación de alimentos. - Pendiente largo: ¡Bien visto! Los pendientes grandes pueden caerse y contaminar los alimentos. No deben llevarse durante la jornada. Personaje 2: - Camiseta de tirantes: ¡Correcto! La ropa de calle no sirve como uniforme. Debe usarse la camisa del uniforme, limpia. - Reloj: ¡Bien! El reloj puede acumular suciedad y microorganismos. Debe retirarse antes de manipular alimentos. - Mancha en el pantalón: ¡Muy bien! El uniforme debe estar limpio. Si se mancha, hay que cambiarlo o limpiarlo. - Sin gorro: ¡Correcto! El gorro de cocina es obligatorio para evitar que el pelo caiga en los alimentos. Personaje 3: - Pendientes enormes: ¡Bien! Los pendientes grandes pueden desprenderse y contaminar los alimentos. Deben retirarse. - Brazalete: ¡Correcto! Las joyas acumulan suciedad y pueden caerse. No deben llevarse durante la manipulación. - Uñas largas: ¡Muy bien! Las uñas deben estar cortas y limpias para evitar acumular suciedad y contaminar los alimentos. - Sin gorro: ¡Correcto! El gorro de cocina es obligatorio para evitar que el pelo caiga en los alimentos. Personaje 4: - Pelo suelto: ¡Bien! El pelo debe llevarse recogido y cubierto por el gorro para evitar que caiga en los alimentos. - Mal olor en las axilas: ¡Correcto! La higiene corporal es imprescindible. Una ropa limpia no sustituye una higiene personal adecuada. - Zapatos de tacón: ¡Muy bien! El calzado debe ser apropiado para trabajar: cerrado, cómodo, antideslizante y seguro. - Uñas pintadas: ¡Bien visto! El esmalte puede desprenderse y caer en los alimentos. Las uñas deben llevarse sin pintar, cortas y limpias. Feedback por error: Si pulsa un elemento que no debe corregirse: Ese elemento no supone un problema para la seguridad alimentaria. | G10: ='Cont-Obj'!E:E -> 2.2 El uniforme y la higiene personal
A11: ='Cont-Obj'!A:A -> Módulo 2. Higiene personal del manipulador | B11: ='Cont-Obj'!B:B -> O2.3 Identificar cómo las manos, el cabello, la barba, las uñas, las joyas y la ropa pueden convertirse en fuentes de contaminación. | C11: ='Cont-Obj'!C:C -> 8 | D11: Vestuario | E11: Título de la actividad: Antes de comenzar, revisa tu uniforme e higiene. Enunciado: Cuatro compañeros están a punto de empezar su jornada en la cocina. Antes de entrar, hay que revisar que su aspecto sea el adecuado: uniforme completo y limpio, higiene personal correcta y sin objetos que puedan contaminar los alimentos o suponer un riesgo. Observa bien a cada personaje y pulsa sobre todos los elementos que deban modificarse, retirarse o corregirse. ¡No se te puede escapar ni uno! Cuando los tengas todos, ese trabajador estará listo para empezar. Descripción: Actividad interactiva de observación y selección. En el centro de la pantalla aparecen cuatro trabajadores en el vestuario, de frente y vestidos con su uniforme (o con elementos que deben corregir). El alumnado debe pulsar sobre cada elemento de la indumentaria o de la higiene personal que deba modificarse, retirarse o corregirse para poder comenzar la jornada de forma higiénica y segura. Se trabaja la importancia del uniforme limpio, la higiene personal y la correcta utilización de los equipos de protección. Personaje 1 – Hombre con camisa blanca, pantalón negro largo, gorro y zapatos negros apropiados. Elementos a corregir: Barba larga → pulsar para poner redecilla de protección. Uñas sucias → pulsar para limpiar la suciedad bajo las uñas. Móvil en el bolsillo → pulsar el bolsillo para retirarlo. Pendiente largo en la oreja → pulsar la oreja para quitarlo. Personaje 2 – Hombre con camiseta de tirantes blanca, pantalón negro y zapatos apropiados. Elementos a corregir: Camiseta de tirantes → pulsar para cambiarla por la camisa del uniforme. Reloj en la muñeca → pulsar la muñeca para quitarlo. Mancha en el pantalón → pulsar la mancha para eliminarla. Sin gorro → pulsar la cabeza para ponerse el gorro de cocina. Personaje 3 – Mujer con camisa blanca, pantalón negro largo y zapatos apropiados. Elementos a corregir: Pendientes enormes → pulsar las orejas para quitarlos. Brazalete → pulsar la muñeca para quitarlo. Uñas largas → pulsar las manos para cortarlas. Sin gorro → pulsar la cabeza para ponerse el gorro de cocina. Personaje 4 – Mujer con camisa blanca, pantalón negro, gorro de cocina y zapatos de tacón. Elementos a corregir: Pelo suelto → pulsar el pelo para recogerlo. Mal olor en las axilas → pulsar las axilas para corregir la higiene personal. Zapatos de tacón → pulsar los zapatos para sustituirlos por calzado apropiado. Uñas pintadas de rojo → pulsar las manos para retirar el esmalte. | F11: Feedback por acierto: Personaje 1: - Barba larga: ¡Bien! La barba puede acumular microorganismos y restos de comida. Debe cubrirse con una redecilla de protección. - Uñas sucias: ¡Correcto! Las uñas sucias son un foco de contaminación. Hay que mantenerlas cortas y limpias. - Móvil en el bolsillo: ¡Muy bien! El móvil acumula microorganismos y no debe llevarse durante la manipulación de alimentos. - Pendiente largo: ¡Bien visto! Los pendientes grandes pueden caerse y contaminar los alimentos. No deben llevarse durante la jornada. Personaje 2: - Camiseta de tirantes: ¡Correcto! La ropa de calle no sirve como uniforme. Debe usarse la camisa del uniforme, limpia. - Reloj: ¡Bien! El reloj puede acumular suciedad y microorganismos. Debe retirarse antes de manipular alimentos. - Mancha en el pantalón: ¡Muy bien! El uniforme debe estar limpio. Si se mancha, hay que cambiarlo o limpiarlo. - Sin gorro: ¡Correcto! El gorro de cocina es obligatorio para evitar que el pelo caiga en los alimentos. Personaje 3: - Pendientes enormes: ¡Bien! Los pendientes grandes pueden desprenderse y contaminar los alimentos. Deben retirarse. - Brazalete: ¡Correcto! Las joyas acumulan suciedad y pueden caerse. No deben llevarse durante la manipulación. - Uñas largas: ¡Muy bien! Las uñas deben estar cortas y limpias para evitar acumular suciedad y contaminar los alimentos. - Sin gorro: ¡Correcto! El gorro de cocina es obligatorio para evitar que el pelo caiga en los alimentos. Personaje 4: - Pelo suelto: ¡Bien! El pelo debe llevarse recogido y cubierto por el gorro para evitar que caiga en los alimentos. - Mal olor en las axilas: ¡Correcto! La higiene corporal es imprescindible. Una ropa limpia no sustituye una higiene personal adecuada. - Zapatos de tacón: ¡Muy bien! El calzado debe ser apropiado para trabajar: cerrado, cómodo, antideslizante y seguro. - Uñas pintadas: ¡Bien visto! El esmalte puede desprenderse y caer en los alimentos. Las uñas deben llevarse sin pintar, cortas y limpias. Feedback por error: Si pulsa un elemento que no debe corregirse: Ese elemento no supone un problema para la seguridad alimentaria. | G11: ='Cont-Obj'!E:E -> 2.3 Cabello, barba, uñas y joyas
A12: ='Cont-Obj'!A:A -> Módulo 2. Higiene personal del manipulador | B12: ='Cont-Obj'!B:B -> O2.4 Ejecutar correctamente el lavado y secado de manos. | C12: ='Cont-Obj'!C:C -> 9 | D12: Cocina (vista fregadero) | E12: Título de la actividad: Manos a la obra: el lavado perfecto. Enunciado: Tus manos son la herramienta más importante… y también la vía más fácil para contaminar un alimento. A la derecha encontrarás la checklist con los pasos para un lavado correcto. Tu misión es completarlos todos en orden. Si te saltas un paso o no completas bien el movimiento, no avanzarás. Solo cuando termines la lista tendrás unas manos listas para manipular alimentos con seguridad. ¿Te atreves? Descripción: Actividad interactiva tipo simulación motora. En pantalla se ven unas manos en primer plano con un fregadero al fondo. El alumnado debe completar el procedimiento de lavado de manos siguiendo una checklist en el lado derecho de la pantalla. Cada paso exige un gesto concreto con el ratón o el dedo sobre las manos. Cuando el gesto se completa correctamente, el ítem se tacha automáticamente. Los pasos deben realizarse en orden: si se intenta ejecutar un paso que no toca, no avanza. Y si toca una superficie en el proceso, empezará de nuevo con el lavado. Se trabaja de forma práctica el procedimiento oficial de lavado de manos. Pasos y gestos que debe realizar el alumnado: - Paso 1. Mojar las manos con agua potable. Gesto: arrastrar el ratón desde las manos hacia el grifo para activarlo y mantener pulsado hasta que el agua cubra las manos. - Paso 2. Aplicar jabón líquido suficiente. Gesto: pulsar el dosificador de jabón (clic) y arrastrar el jabón hasta las manos. - Paso 3. Frotar durante al menos 20 segundos. Gesto: frotar las palmas entre sí con movimientos circulares y rápidos. Aparece un contador de 20 segundos en pantalla que solo avanza mientras se frota. - Paso 4. Limpiar bien las palmas, el dorso, los espacios entre los dedos, las yemas, los pulgares, las uñas y las muñecas. Gesto: secuencia guiada por símbolos en pantalla: Palmas: círculos amplios con ambas manos enfrentadas. Dorso: movimiento de arriba abajo con los dedos entrelazados. Espacios entre los dedos: zigzag entre los dedos. Yemas: pequeños círculos con las puntas de los dedos sobre la palma contraria. Pulgares: giros circulares alrededor del pulgar. Uñas: frotar las uñas contra la palma contraria. Muñecas: círculos alrededor de la muñeca. A medida que el alumnado completa cada zona, aparecen marcas de verificación parciales dentro del propio paso. - Paso 5. Aclarar completamente con agua corriente. Gesto: arrastrar de nuevo hacia el grifo y mantener hasta que desaparezca toda la espuma. - Paso 6. Secar bien las manos utilizando el sistema higiénico establecido, preferiblemente papel desechable. Gesto: coger una toalla de papel (clic) y frotarla sobre las manos con movimiento de arriba abajo hasta que queden secas. | F12: Feedback por acierto: Paso 1 – ¡Bien hecho! Paso 2 – ¡Muy bien! Paso 3 – ¡Perfecto! Paso 4 – ¡Estupendo! Paso 5 – ¡Fabuloso! Paso 6 – ¡Excelente! Paso 7 – ¡Crack! Feedback de error: Si intenta ejecutar un paso que no toca: "Aún no es el turno de ese paso. Sigue la checklist en orden: cada paso prepara el siguiente." Si en algún momento toca alguna superficie: "Has tocado una superficie contaminada. Después del lavado, evita pomos, grifos y alimentos crudos: volverías a contaminar las manos." Empieza de nuevo el lavado de manos. | G12: ='Cont-Obj'!E:E -> 2.4 El lavado de manos
A13: ='Cont-Obj'!A:A -> Módulo 2. Higiene personal del manipulador | B13: ='Cont-Obj'!B:B -> O2.5 Identificar en qué situaciones deben ser lavadas las manos | C13: ='Cont-Obj'!C:C -> 10 | D13: Cocina | E13: Título de la actividad: ¿Te lavarías las manos? Enunciado: Durante tu jornada, tus manos tocan decenas de cosas, y no todas ellas son igual de seguras. En pantalla irán apareciendo situaciones reales de trabajo. En cada una, decide si es necesario lavarse las manos antes de continuar. Cada situación es independiente: no te dejes llevar por lo que hayas respondido antes. ¡Demuestra que sabes cuándo toca lavarse las manos! Descripción: Actividad interactiva de decisión binaria. Se presentan, una a una, tarjetas pictograma con situaciones cotidianas de la jornada de un manipulador de alimentos. Cada tarjeta incluye una ilustración y una breve definición. Bajo la tarjeta aparecen dos cajones: Sí y No. El alumnado debe decidir si en esa situación es necesario lavarse las manos antes de continuar con otra tarea. Las situaciones se alternan para que el alumnado valore cada caso de forma independiente, sin dejarse llevar por la inercia. Situaciones a valorar: 1. Acabas de cobrar con dinero en efectivo --> Si 2. Tus manos están limpias y vas a cortar verduras en una tabla límpia --> No 3. Acabas de tocarte el pelo --> Si 4. Acabas de etiquetar un envase con la fecha --> No 5. Acabas de usar el teléfono móvil --> Si 6. Vas a servir un plato ya terminado --> No 7. Acabas de sonarte la nariz --> Si 8. Acabas de colocar los cubiertos limpios y secos y ahora tocan los platos --> No 9. Acabas de fregar el suelo con la fregona --> Sí 10. Acabas de recoger algo del suelo --> Si 11. Tus manos están limpias y vas a doblar unas servilletas --> No 12. Acabas de limpiar la encimera con un producto químico --> Si 13. Vas a emplatar unas verduras ya lavadas --> No 14. Has terminado de preparar el pollo y tienes que cortar verdura --> Si | F13: 1. ¡Correcto! / Incorrecto: El dinero pasa por muchas manos y es una fuente de contaminación. Después de tocarlo, hay que lavarse las manos antes de manipular alimentos. 2. ¡Correcto! / Incorrecto: No ha habido contacto con ninguna fuente de contaminación y la tabla está limpia. No es necesario un nuevo lavado por ese motivo. 3. ¡Correcto! / Incorrecto: El pelo puede acumular grasa, polvo y microorganismos. Después de tocarlo, hay que lavarse las manos antes de seguir manipulando alimentos. 4. ¡Correcto! / Incorrecto: Etiquetar un envase no implica contacto con fuentes de contaminación. No es necesario lavarse las manos por ese motivo. 5. ¡Correcto! / Incorrecto: El móvil es uno de los objetos que más microorganismos acumula y rara vez se limpia. Tras usarlo, hay que lavarse las manos. 6. ¡Correcto! / Incorrecto: Si las manos están limpias y no han tocado nada contaminante, no es necesario un nuevo lavado para servir un plato terminado. 7. ¡Correcto! / Incorrecto: Sonarse la nariz contamina las manos con secreciones y microorganismos. Es obligatorio lavarse las manos inmediatamente después. 8. ¡Correcto! / Incorrecto: Los platos ya están limpios y secos, y la tarea no implica contacto con fuentes de contaminación. No hace falta un nuevo lavado. 9. ¡Correcto! / Incorrecto: La fregona, el agua sucia y el suelo son fuentes claras de contaminación. Después de fregar, hay que lavarse las manos antes de tocar alimentos. 10. ¡Correcto! / Incorrecto: El suelo es una de las superficies más contaminadas. Después de recoger algo del suelo, hay que lavarse las manos. 11. ¡Correcto! / Incorrecto: Doblar servilletas limpias no implica contacto con fuentes de contaminación. No es necesario lavarse las manos por ese motivo. 12. ¡Correcto! / Incorrecto: Los productos químicos de limpieza pueden dejar residuos en las manos y contaminar los alimentos. Hay que lavarse las manos después de usarlos. 13. ¡Correcto! / Incorrecto: Si las manos están limpias y las verduras ya han sido lavadas, no es necesario un nuevo lavado para emplatarlas. 14. ¡Correcto! / Incorrecto: El pollo crudo es una fuente importante de contaminación. Al cambiar de tarea, hay que lavarse las manos para evitar contaminar la verdura. | G13: ='Cont-Obj'!E:E -> 2.4 El lavado de manos
A14: ='Cont-Obj'!A:A -> Módulo 2. Higiene personal del manipulador | B14: ='Cont-Obj'!B:B -> O2.6 Determinar cuándo es necesario cambiar los guantes y cómo utilizarlos de forma segura. | C14: ='Cont-Obj'!C:C -> 11 | E14: Actividad de lectura: Enunciado: | G14: ='Cont-Obj'!E:E -> 2.5 El uso correcto de los guantes
A15: ='Cont-Obj'!A:A -> Módulo 2. Higiene personal del manipulador | B15: ='Cont-Obj'!B:B -> O2.7 Aplicar el procedimiento establecido ante heridas y lesiones durante la manipulación de alimentos. | C15: ='Cont-Obj'!C:C -> 12 | D15: Cocina (pared botiquín) | E15: Título de la actividad: Heridas a raya: protege, decide y trabaja seguro. Enunciado: Parte 1 – Simulación: Te has hecho una pequeña herida en la mano y estás en plena jornada en la cocina. Antes de volver a manipular alimentos, debes protegerla correctamente. Alrededor de tus manos tienes varias herramientas. Selecciona y ejecuta los pasos necesarios para dejar la herida limpia y bien cubierta. Parte 2 – Test: Ahora demuestra que sabes decidir. En cada situación, elige la opción correcta. Descripción: Actividad mixta de simulación + test. En la primera parte, el alumnado ve unas manos en primer plano con una pequeña herida y debe ejecutar correctamente los pasos para protegerla antes de volver a manipular alimentos. En la segunda parte, se plantean distintas situaciones relacionadas con lesiones en forma de test de 3 opciones (solo una correcta). Se trabajan las normas de actuación ante heridas, cortes y otras lesiones de la piel en el entorno alimentario. Pasos de la simulación (estos pasos no aparecen escritos, el alumnado actua por descubrimiento): Paso 1. Limpiar y desinfectar correctamente la herida. Gesto: pulsar el algodón (se moverá al centro de la pantalla)→ arrastrar el bote de desinfectante de heridas al algodón (se humedecerá y desaparecerá el bote)→ frotar suavemente sobre la herida (tras esto, desaparecerá el algodón) Paso 2. Protegerla con un apósito impermeable y bien ajustado. Gesto: pulsar el apósito (se moverá al centro de la pantalla)→ pulsar las tijeras y llévalas al apósito (se cortará el apósito y desaparecerá la tijera) → pulsar sobre la herida para colocarlo → arrastrar el ratón sobre el apósito para pegarlo bien. Paso 3. Colocarse un guante de un solo uso cuando exista riesgo de que el apósito pueda desprenderse. Gesto: pulsar el guante → arrastrarlo hasta la mano para colocarlo. Situaciones tipo test: 1. Herida limpia y correctamente cubierta con un apósito impermeable. ✅ Puede continuar trabajando. ❌ Debe informar al responsable y dejar de manipular alimentos. ❌ Debe retirarse el apósito antes de continuar. 2. Herida en la mano cubierta, pero el apósito puede desprenderse durante el trabajo. ✅ Debe protegerse además con un guante de un solo uso. ❌ Puede continuar sin cambios, porque la herida ya está cubierta. ❌ Debe informar al responsable y abandonar la manipulación de alimentos. 3. Herida con presencia de pus. ✅ Debe informar al responsable. ❌ Puede continuar si se limpia con alcohol antes de trabajar. ❌ Puede continuar si se cubre con doble apósito. 4. Herida que no puede cubrirse completamente con un apósito ni con un guante. ✅ Debe informar al responsable. ❌ Puede continuar si se coloca un guante por encima. ❌ Puede continuar si evita tocar los alimentos directamente. 5. Lesión que te impide mover la mano con normalidad y trabajar de forma segura. ✅ Debe informar al responsable para valorar un cambio de tarea o dejar de manipular alimentos. ❌ Puede continuar si se coloca un guante de un solo uso. ❌ Puede continuar si se cubre la lesión con un apósito impermeable. | F15: Parte 1 – Simulación: Por cada paso correcto, refuerzo positivo: ¡Bien hecho! ¡Muy bien! ¡Perfecto! ¡Estupendo! ¡Excelente! Si no pulsa donde toca simplemente no pasa nada, no avanza. Parte 2 – Test: 1. Herida limpia y bien cubierta con apósito impermeable. ¡Correcto! / Incorrecto: Si la herida está limpia y correctamente cubierta con un apósito impermeable, se puede continuar trabajando con normalidad. 2. Herida cubierta, pero el apósito puede desprenderse. ¡Correcto! / Incorrecto: Si existe riesgo de que el apósito se desprenda durante el trabajo, hay que proteger la herida además con un guante de un solo uso. 3. Herida abierta y sin proteger. ¡Correcto! / Incorrecto: Nunca se deben manipular alimentos con una herida abierta y sin proteger. Es una fuente directa de contaminación. 4. Herida infectada. ¡Correcto! / Incorrecto: Una herida infectada puede contener microorganismos peligrosos. Es obligatorio informar al responsable antes de continuar. 5. Herida con presencia de pus. ¡Correcto! / Incorrecto: La presencia de pus indica infección. No se debe manipular alimentos y hay que informar al responsable de inmediato. 6. Herida que no puede cubrirse adecuadamente. ¡Correcto! / Incorrecto: Si la herida no puede cubrirse bien, no hay garantía de que no contamine los alimentos. Hay que informar al responsable. 7. Lesión que impide trabajar de forma segura. ¡Correcto! / Incorrecto: Si la lesión impide trabajar con seguridad, hay que informar al responsable para que valore un cambio de tarea o dejar de manipular alimentos. | G15: ='Cont-Obj'!E:E -> 2.6 Heridas y cortes
A16: ='Cont-Obj'!A:A -> Módulo 3. Manipulación segura de los alimentos | B16: ='Cont-Obj'!B:B -> O3.1 Identificar qué es la contaminación alimentaria y reconocer cómo puede producirse a lo largo de las distintas etapas de la cadena alimentaria. | C16: ='Cont-Obj'!C:C -> 13 | E16: Actividad de lectura: Enunciado: | G16: ='Cont-Obj'!E:E -> 3.1 ¿Qué es la contaminación alimentaria?
A17: ='Cont-Obj'!A:A -> Módulo 3. Manipulación segura de los alimentos | B17: ='Cont-Obj'!B:B -> O3.2 Distinguir los diferentes tipos de contaminación alimentaria: biológica, física y química. | C17: ='Cont-Obj'!C:C -> 14 | E17: Actividad de lectura: Enunciado: | G17: ='Cont-Obj'!E:E -> 3.2 ¿Cómo pueden contaminarse los alimentos?
A18: ='Cont-Obj'!A:A -> Módulo 3. Manipulación segura de los alimentos | B18: ='Cont-Obj'!B:B -> O3.3 Identificar las principales fuentes y vías de contaminación de los alimentos durante su manipulación. | C18: ='Cont-Obj'!C:C -> 15 | E18: Título de la actividad: Tras la barra. Enunciado: Estás detrás de la barra y varios clientes se acercan con quejas sobre sus platos. Algo ha ido mal en la cocina y tu misión es descubrir qué tipo de contaminación ha afectado a cada alimento: física, química o biológica. Haz clic en cada plato para investigarlo. En algunos casos verás la evidencia directamente; en otros, tendrás que revisar las cámaras de seguridad pulsando el icono de la cámara. Observa bien, reúne las pistas y selecciona el tipo de contaminación. ¡Demuestra que no se te escapa nada!" Descripción: Actividad interactiva de investigación. El alumnado se sitúa detrás de la barra de un establecimiento y varios clientes se acercan con quejas sobre distintos platos. Al hacer clic en cada plato, se muestra en primer plano (vista desde arriba). Según el caso, habrá una evidencia visible (pelo, plástico, moho…) o no, en cuyo caso aparecerá un icono de cámara para revisar las grabaciones de seguridad de la cocina en el momento de la preparación. Una vez reunida la pista, el alumnado debe identificar el tipo de contaminación: física, química o biológica. Se trabajan los tres tipos de contaminación y la importancia de no fiarse solo de los sentidos. CASO 1 Cliente: "He encontrado un pelo en la comida. No es mío, yo llevo el pelo recogido." Qué ve el alumnado al revisar el plato: Hay un cabello largo y oscuro, claramente visible, que no forma parte del plato. Respuesta: Contaminación física. CASO 2 Cliente: "No he notado nada raro en el plato, pero después de comerlo me he encontrado mal." Qué ve el alumnado al revisar el plato: No se aprecia ningún objeto extraño ni alteración visible. El alimento parece normal a la vista. Aparece el icono de cámara en la esquina superior derecha. Qué ve el alumnado en las cámaras: Se observa cómo, durante la preparación, el manipulador utiliza un utensilio que acababa de estar en contacto con carne cruda y no lo ha lavado antes de utilizarlo con este alimento. El utensilio pasa directamente de un alimento crudo a este plato. Respuesta: Contaminación biológica. CASO 3 Cliente: "Al masticar he notado algo duro. Creo que hay un trozo de algo que no es comida." Qué ve el alumnado al revisar el plato: Entre los alimentos hay un pequeño fragmento de plástico (un trozo de un envase), claramente visible. Respuesta: Contaminación física. CASO 4 Cliente: "El plato tiene un sabor raro, como a producto de limpieza. Sabe mal." Qué ve el alumnado al revisar el plato: El plato se ve completamente normal: buen aspecto, buen color, sin objetos extraños. Aparece el icono de cámara. Qué ve el alumnado en las cámaras: En la grabación se observa cómo, durante la limpieza de la zona de trabajo, se utilizó un producto químico y quedaron restos del producto sobre una superficie que posteriormente entró en contacto con este alimento. El manipulador no aclaró ni secó bien la superficie antes de apoyar el alimento. Respuesta: Contaminación química. CASO 5 Cliente: "El plato olía raro y, después de comerlo, he empezado a encontrarme mal." Qué ve el alumnado al revisar el plato: El plato se ve completamente normal: buen aspecto, buen olor, sin alteraciones visibles. Aparece el icono de cámara. Qué ve el alumnado en las cámaras: Se observa cómo, durante la preparación, el manipulador manipula el alimento con las manos sin lavárselas después de haber tocado basura. Los microorganismos pasan al alimento sin dejar rastro visible. Respuesta: Contaminación biológica. CASO 6 Cliente: "Creo que hay algo en el plato que no es comida. Parece un trozo de algo… de un pendiente, quizá." Qué ve el alumnado al revisar el plato: Entre los alimentos, hay un pequeño elemento procedente de un objeto personal del manipulador (la tuerca de un pendiente), claramente visible. Respuesta: Contaminación física. CASO 7 Cliente: «La salsa tiene un sabor extraño. No sé qué le habéis puesto, pero no sabe como siempre». Qué ve el alumnado al revisar el plato: El plato parece normal a simple vista, sin objetos extraños ni alteraciones visibles. Aparece el icono de cámara. Qué ve el alumnado en las cámaras: En la grabación se observa cómo un manipulador utiliza un bote de salsa que se había almacenado junto a un producto químico para el control de plagas. El exterior del bote se ha contaminado con restos del producto y, al abrirlo y manipularlo, estos entran en contacto con la salsa. Respuesta: Contaminación química. | F18: Caso 1 – Cabello en el plato: ¡Correcto! / Incorrecto: Un cabello es un objeto extraño que no debería estar en el alimento. Es una contaminación física. Caso 2 – Olor extraño por utensilio sucio: ¡Correcto! / Incorrecto: Los microorganismos del alimento crudo han pasado al plato a través de un utensilio sucio. Es una contaminación biológica, y no se ve a simple vista. Caso 3 – Fragmento de plástico: ¡Correcto! / Incorrecto: Un fragmento de plástico es un objeto ajeno al alimento. Es una contaminación física. Caso 4 – Sabor a producto de limpieza: ¡Correcto! / Incorrecto: Los restos de productos químicos de limpieza han entrado en contacto con el alimento. Es una contaminación química. Caso 5 – Alimento aparentemente normal que causa enfermedad: ¡Correcto! / Incorrecto: Los microorganismos pueden estar en el alimento sin que se vean, huelan o sepan. Es una contaminación biológica. Caso 6 – Objeto personal en el plato: ¡Correcto! / Incorrecto: Los objetos personales pueden desprenderse y caer en la comida. Es una contaminación física. Caso 7 – Restos de producto de limpieza: ¡Correcto! / Incorrecto: Los restos de productos de limpieza pueden contaminar el alimento si no se aclaran bien las superficies. Es una contaminación química. Feedback de error general (si el alumnado elige mal el tipo de contaminación): Si confunde física: "Recuerda: la contaminación física aparece cuando en el alimento se encuentra un objeto o elemento que no debería estar presente." Si confunde química: "Recuerda: la contaminación química se produce cuando el alimento entra en contacto con una sustancia química perjudicial." Si confunde biológica: "Recuerda: la contaminación biológica se produce cuando el alimento contiene microorganismos o parásitos capaces de causar enfermedades." | G18: ='Cont-Obj'!E:E -> 3.2 ¿Cómo pueden contaminarse los alimentos?
A19: ='Cont-Obj'!A:A -> Módulo 3. Manipulación segura de los alimentos | B19: ='Cont-Obj'!B:B -> O3.4 Comprender cómo se produce la contaminación cruzada. | C19: ='Cont-Obj'!C:C -> 16 | E19: Actividad de lectura: Enunciado: Idea: Incluir información sobre la contaminación directa e indirecta. Los alimentos crudos pueden contener microorganismos que contaminen otros alimentos. La contaminación cruzada ocurre cuando esos microorganismos pasan de un alimento, una superficie, un utensilio o las manos a otro alimento. Puede producirse por contacto directo entre alimentos o de forma indirecta a través de manos, utensilios y superficies. Los alimentos listos para consumir deben mantenerse protegidos y separados de posibles fuentes de contaminación. Cuando cambies de tarea, debes evitar que la contaminación pase al siguiente alimento. | G19: ='Cont-Obj'!E:E -> 3.3 La contaminación cruzada
